<?xml version="1.0"?>
<robot name="robo_cat">

  <material name="grey">
    <color rgba="0.5 0.5 0.5 1"/>
  </material>
  <material name="white">
    <color rgba="0.9 0.9 0.9 1"/>
  </material>
  <material name="black">
    <color rgba="0.1 0.1 0.1 1"/>
  </material>

  <link name="world"/>

  <joint name="fixed_base" type="fixed">
    <parent link="world"/>
    <child link="front_body"/>
    <origin xyz="0 0 2" rpy="0 0 0"/> </joint>

  <link name="front_body">
    <visual>
      <geometry>
        <box size="0.1 0.1 0.1"/>
      </geometry>
      <origin xyz="0 0 0" rpy="0 1.5708 0"/> 
      <material name="white"/>
    </visual>
    <inertial>
      <mass value="1.0"/>
      <inertia ixx="0.00125" ixy="0" ixz="0" iyy="0.00146" iyz="0" izz="0.00146"/>
    </inertial>
  </link>

  <link name="spine_1">
    <visual>
      <geometry>
        <cylinder length="0.02" radius="0.05"/>
      </geometry>
      <origin xyz="0.05 -0.01 0" rpy="1.5708 0 0"/>
      <material name="white"/>
    </visual>
    <inertial>
      <mass value="0.2"/>
      <inertia ixx="0.0001" ixy="0" ixz="0" iyy="0.0001" iyz="0" izz="0.0001"/>
    </inertial>
  </link>

  <link name="spine_2">
    <visual>
      <geometry>
        <cylinder length="0.02" radius="0.05"/>
      </geometry>
      <origin xyz="0 0.01 0" rpy="1.5708 0 0"/>
      <material name="black"/>
    </visual>
    <inertial>
      <mass value="0.2"/>
      <inertia ixx="0.0001" ixy="0" ixz="0" iyy="0.0001" iyz="0" izz="0.0001"/>
    </inertial>
  </link>

  <link name="rear_body">
    <visual>
      <geometry>
        <box size="0.1 0.1 0.1"/>
      </geometry>
      <origin xyz="0.05 0 0" rpy="0 1.5708 0"/>
      <material name="black"/>
    </visual>
    <inertial>
      <mass value="1.0"/>
      <inertia ixx="0.00125" ixy="0" ixz="0" iyy="0.00146" iyz="0" izz="0.00146"/>
    </inertial>
  </link>

  <link name="tail">
    <visual>
      <geometry>
        <cylinder length="0.15" radius="0.01"/>
      </geometry>
      <origin xyz="0.075 0 0" rpy="0 1.5708 0"/>
      <material name="grey"/>
    </visual>
    <inertial>
      <mass value="0.1"/>
      <inertia ixx="0.00001" ixy="0" ixz="0" iyy="0.0002" iyz="0" izz="0.0002"/>
    </inertial>
  </link>

  <joint name="joint1" type="revolute">
    <parent link="front_body"/>
    <child link="spine_1"/>
    <origin xyz="0.05 0 0" rpy="0 0 0"/> <axis xyz="1 0 0"/> <limit lower="-4.71" upper="4.71" effort="10.0" velocity="5.0"/>
  </joint>

  <joint name="joint2" type="revolute">
    <parent link="spine_1"/>
    <child link="spine_2"/>
    <origin xyz="0.05 0 0" rpy="0 0 0"/> <axis xyz="0 1 0"/> <limit lower="-1.57" upper="1.57" effort="10.0" velocity="5.0"/>
  </joint>

  <joint name="joint3" type="revolute">
    <parent link="spine_2"/>
    <child link="rear_body"/>
    <origin xyz="0.05 0 0" rpy="0 0 0"/> <axis xyz="1 0 0"/> <limit lower="-4.71" upper="4.71" effort="10.0" velocity="5.0"/>
  </joint>

  <joint name="joint4" type="revolute">
    <parent link="rear_body"/>
    <child link="tail"/>
    <origin xyz="0.1 0 0" rpy="0 0 0"/> <axis xyz="0 1 0"/> <limit lower="-1.57" upper="1.57" effort="5.0" velocity="10.0"/>
  </joint>

  <transmission name="trans_joint1">
    <type>transmission_interface/SimpleTransmission</type>
    <joint name="joint1">
      <hardwareInterface>hardware_interface/EffortJointInterface</hardwareInterface>
    </joint>
    <actuator name="motor1">
      <mechanicalReduction>1</mechanicalReduction>
    </actuator>
  </transmission>

  <transmission name="trans_joint2">
    <type>transmission_interface/SimpleTransmission</type>
    <joint name="joint2">
      <hardwareInterface>hardware_interface/EffortJointInterface</hardwareInterface>
    </joint>
    <actuator name="motor2">
      <mechanicalReduction>1</mechanicalReduction>
    </actuator>
  </transmission>

  <transmission name="trans_joint3">
    <type>transmission_interface/SimpleTransmission</type>
    <joint name="joint3">
      <hardwareInterface>hardware_interface/EffortJointInterface</hardwareInterface>
    </joint>
    <actuator name="motor3">
      <mechanicalReduction>1</mechanicalReduction>
    </actuator>
  </transmission>

  <transmission name="trans_joint4">
    <type>transmission_interface/SimpleTransmission</type>
    <joint name="joint4">
      <hardwareInterface>hardware_interface/EffortJointInterface</hardwareInterface>
    </joint>
    <actuator name="motor4">
      <mechanicalReduction>1</mechanicalReduction>
    </actuator>
  </transmission>

</robot>